<?xml version="1.0" encoding="utf-8"?>
<robot name="airbot">
  <link name="world" />
  <joint name="floating_base" type="floating">
    <origin rpy="0 0 0" xyz="0 0 0" />
    <parent link="world" />
    <child link="base_link" />
  </joint>
  <link name="base_link">
    <inertial>
      <origin xyz="0.018885 0.00062964 0.06018" rpy="0 0 0" />
      <mass value="4.6733" />
      <inertia ixx="0.03365269" ixy="-0.00062692" ixz="-0.00486887" iyy="0.03473902" iyz="0.00024269" izz="0.05345228" />
    </inertial>
    <visual>
      <origin xyz="0 0 0" rpy="0 0 0" />
      <geometry>
        <mesh filename="../meshes/chassis/base_link.STL" />
      </geometry>
      <material name="">
        <color rgba="0.75294 0 0 1" />
      </material>
    </visual>
    <collision>
      <origin xyz="0 0 0" rpy="0 0 0" />
      <geometry>
        <mesh filename="../meshes/chassis/base_link.STL" />
      </geometry>
    </collision>
  </link>

  

  <!-- right leg -->
  <link name="right_thigh">
    <inertial>
      <origin xyz="0.17494 0.0025279 -0.012308" rpy="0 0 0" />
      <mass value="1.3343" />
      <inertia ixx="0.00127772" ixy="0.00031117" ixz="-0.00051742" iyy="0.00919068" iyz="-8.19e-06" izz="0.00982095" />
    </inertial>
    <visual>
      <origin xyz="0 0 0" rpy="0 0 0" />
      <geometry>
        <mesh filename="../meshes/chassis/right_thigh.STL" />
      </geometry>
      <material name="">
        <color rgba="0.75294 0.75294 0 1" />
      </material>
    </visual>
    <collision>
      <origin xyz="0 0 0" rpy="0 0 0" />
      <geometry>
        <mesh filename="../meshes/chassis/right_thigh.STL" />
      </geometry>
    </collision>
  </link>
  <joint name="right_hip" type="revolute">
    <origin xyz="0.017241 -0.13501 0.0613" rpy="1.5708 1.5708 3.1416" />
    <parent link="base_link" />
    <child link="right_thigh" />
    <axis xyz="0 0 1" />
    <limit lower="-0.654" upper="2.225" effort="35" velocity="20" />
  </joint>
  <link name="right_shin">
    <inertial>
      <origin xyz="0.15612 0.00046556 -0.020119" rpy="0 0 0" />
      <mass value="0.94398" />
      <inertia ixx="0.00075022" ixy="-3.799e-05" ixz="-0.00046442" iyy="0.00358634" iyz="8.81e-06" izz="0.00389927" />
    </inertial>
    <visual>
      <origin xyz="0 0 0" rpy="0 0 0" />
      <geometry>
        <mesh filename="../meshes/chassis/right_shin.STL" />
      </geometry>
      <material name="">
        <color rgba="0.75294 0.75294 0 1" />
      </material>
    </visual>
    <collision>
      <origin xyz="0 0 0" rpy="0 0 0" />
      <geometry>
        <mesh filename="../meshes/chassis/right_shin.STL" />
      </geometry>
    </collision>
  </link>
  <joint name="right_knee" type="revolute">
    <origin xyz="0.21 0 -0.0475" rpy="0 0 0" />
    <parent link="right_thigh" />
    <child link="right_shin" />
    <axis xyz="0 0 1" />
    <limit lower="-2.243" upper="0" effort="35" velocity="20" />
  </joint>
  <link name="right_wheel">
    <inertial>
      <origin xyz="-9.7145E-17 1.3878E-16 -0.0012686" rpy="0 0 0" />
      <mass value="0.44583" />
      <inertia ixx="0.00076522" ixy="0" ixz="0" iyy="0.00076522" iyz="0" izz="0.0014254" />
    </inertial>
    <visual>
      <origin xyz="0 0 0" rpy="0 0 0" />
      <geometry>
        <mesh filename="../meshes/chassis/right_wheel.STL" />
      </geometry>
      <material name="">
        <color rgba="0.75294 0 0 1" />
      </material>
    </visual>
    <collision>
      <origin xyz="0 0 0" rpy="0 0 0" />
      <geometry>
        <mesh filename="../meshes/chassis/right_wheel.STL" />
      </geometry>
    </collision>
  </link>
  <joint name="right_ankle" type="revolute">
    <origin xyz="0.18 0 -0.0305" rpy="0 0 0" />
    <parent link="right_shin" />
    <child link="right_wheel" />
    <axis xyz="0 0 1" />
    <limit lower="-999999" upper="999999" effort="35" velocity="20" />
     <!--   -->
  </joint>

    <!-- arm -->

  <joint
    name="trunk_arm_joint_base_0"
    type="fixed"
    dont_collapse="true">
    <origin
      xyz="0 0 0"
      rpy="0 0 0" />
    <parent
      link="base_link" />
    <child
      link="arm_link00" />
    <axis
      xyz="0 0 0" />
  </joint>
  <link
    name="arm_link00">
    <inertial>
      <origin 
        xyz="-0.00473641164191482 2.56829134630247E-05 0.041451518036016" 
        rpy="0 0 0" />
      <mass 
        value="1.02" />
      <inertia 
        ixx="0.00267433" 
        ixy="-0.00000073" 
        ixz="-0.00017389" 
        iyy="0.00282612" 
        iyz="0.0000004" 
        izz="0.00089624" />
    </inertial>
    <visual>
      <origin
        xyz="0 0 0"
        rpy="0 0 0" />
      <geometry>
        <mesh
          filename="../meshes/piper/base_link.STL" />
      </geometry>
      <material
        name="">
        <color
          rgba="0.792156862745098 0.819607843137255 0.933333333333333 1" />
      </material>
    </visual>
    <collision>
      <origin
        xyz="0 0 0"
        rpy="0 0 0" />
      <geometry>
        <mesh
          filename="../meshes/piper/base_link.STL" />
      </geometry>
    </collision>
  </link>
  <link
    name="arm_link01">
    <inertial>
      <origin 
        xyz="0.000121504734057468 0.000104632162460536 -0.00438597309559853" 
        rpy="0 0 0" />
      <mass 
        value="0.71" />
      <inertia 
        ixx="0.00048916" 
        ixy="-0.00000036" 
        ixz="-0.00000224" 
        iyy="0.00040472" 
        iyz="-0.00000242" 
        izz="0.00043982" />
    </inertial>
    <visual>
      <origin
        xyz="0 0 0"
        rpy="0 0 0" />
      <geometry>
        <mesh
          filename="../meshes/piper/link1.STL" />
      </geometry>
      <material
        name="">
        <color
          rgba="0.792156862745098 0.819607843137255 0.933333333333333 1" />
      </material>
    </visual>
    <collision>
      <origin
        xyz="0 0 0"
        rpy="0 0 0" />
      <geometry>
        <mesh
          filename="../meshes/piper/link1.STL" />
      </geometry>
    </collision>
  </link>
  <joint
    name="arm_joint00"
    type="revolute">
    <origin
      xyz="0 0 0.123"
      rpy="0 0 0" />
    <parent
      link="arm_link00" />
    <child
      link="arm_link01" />
    <axis
      xyz="0 0 1" />
    <limit
      lower="-2.618"
      upper="2.168"
      effort="100"
      velocity="5" />
  </joint>
  <link
    name="arm_link02">
    <inertial>
      <origin 
        xyz="0.198666145229743 -0.010926924140076 0.00142121714502687" 
        rpy="0 0 0" />
      <mass 
        value="1.17" />
      <inertia 
        ixx="0.00116918" 
        ixy="-0.00180037" 
        ixz="0.00025146" 
        iyy="0.06785384" 
        iyz="-0.00000455" 
        izz="0.06774489" />
    </inertial>
    <visual>
      <origin
        xyz="0 0 0"
        rpy="0 0 0" />
      <geometry>
        <mesh
          filename="../meshes/piper/link2.STL" />
      </geometry>
      <material
        name="">
        <color
          rgba="0.792156862745098 0.819607843137255 0.933333333333333 1" />
      </material>
    </visual>
    <collision>
      <origin
        xyz="0 0 0"
        rpy="0 0 0" />
      <geometry>
        <mesh
          filename="../meshes/piper/link2.STL" />
      </geometry>
    </collision>
  </link>
  <joint
    name="arm_joint01"
    type="revolute">
    <origin
      xyz="0 0 0"
      rpy="1.5708 -0.1359 -3.1416" />
      <!-- rpy="1.5708 -0.10095-0.03490659 -3.1416" /> -->
    <parent
      link="arm_link01" />
    <child
      link="arm_link02" />
    <axis
      xyz="0 0 1" />
    <limit
      lower="0"
      upper="3.14"
      effort="100"
      velocity="5" />
  </joint>
  <link
    name="arm_link03">
    <inertial>
      <origin 
        xyz="-0.0202737662122021 -0.133914995944595 -0.000458682652737356" 
        rpy="0 0 0" />
      <mass 
        value="0.5" />
      <inertia 
        ixx="0.01361711" 
        ixy="0.00165794" 
        ixz="-0.00000048" 
        iyy="0.00045024" 
        iyz="-0.00000045" 
        izz="0.01380322" />
    </inertial>
    <visual>
      <origin
        xyz="0 0 0"
        rpy="0 0 0" />
      <geometry>
        <mesh
          filename="../meshes/piper/link3.STL" />
      </geometry>
      <material
        name="">
        <color
          rgba="0.792156862745098 0.819607843137255 0.933333333333333 1" />
      </material>
    </visual>
    <collision>
      <origin
        xyz="0 0 0"
        rpy="0 0 0" />
      <geometry>
        <mesh
          filename="../meshes/piper/link3.STL" />
      </geometry>
    </collision>
  </link>
  <joint
    name="arm_joint02"
    type="revolute">
    <origin
      xyz="0.28503 0 0"
      rpy="0 0 -1.7939" />
      <!-- rpy="0 0 -1.759-0.03490659" /> -->
    <parent
      link="arm_link02" />
    <child
      link="arm_link03" />
    <axis
      xyz="0 0 1" />
    <limit
      lower="-2.967"
      upper="0"
      effort="100"
      velocity="5" />
  </joint>
  <link
    name="arm_link04">
    <inertial>
      <origin 
        xyz="-9.66635791618542E-05 0.000876064475651083 -0.00496880904640868" 
        rpy="0 0 0" />
      <mass 
        value="0.38" />
      <inertia 
        ixx="0.00018501" 
        ixy="0.00000054" 
        ixz="0.00000120" 
        iyy="0.00018965" 
        iyz="-0.00000841" 
        izz="0.00015484" />
    </inertial>
    <visual>
      <origin
        xyz="0 0 0"
        rpy="0 0 0" />
      <geometry>
        <mesh
          filename="../meshes/piper/link4.STL" />
      </geometry>
      <material
        name="">
        <color
          rgba="0.792156862745098 0.819607843137255 0.933333333333333 1" />
      </material>
    </visual>
    <collision>
      <origin
        xyz="0 0 0"
        rpy="0 0 0" />
      <geometry>
        <mesh
          filename="../meshes/piper/link4.STL" />
      </geometry>
    </collision>
  </link>
  <joint
    name="arm_joint03"
    type="revolute">
    <origin
      xyz="-0.021984 -0.25075 0"
      rpy="1.5708 0 0" />
    <parent
      link="arm_link03" />
    <child
      link="arm_link04" />
    <axis
      xyz="0 0 1" />
    <limit
      lower="-1.745"
      upper="1.745"
      effort="100"
      velocity="5" />
  </joint>
  <link
    name="arm_link05">
    <inertial>
      <origin 
        xyz="-4.10554118924211E-05 -0.0566486692356075 -0.0037205791677906" 
        rpy="0 0 0" />
      <mass 
        value="0.383" />
      <inertia 
        ixx="0.00166169" 
        ixy="0.00000006" 
        ixz="-0.00000007" 
        iyy="0.00018510" 
        iyz="0.00001026" 
        izz="0.00164321" />
    </inertial>
    <visual>
      <origin
        xyz="0 0 0"
        rpy="0 0 0" />
      <geometry>
        <mesh
          filename="../meshes/piper/link5.STL" />
      </geometry>
      <material
        name="">
        <color
          rgba="0.792156862745098 0.819607843137255 0.933333333333333 1" />
      </material>
    </visual>
    <collision>
      <origin
        xyz="0 0 0"
        rpy="0 0 0" />
      <geometry>
        <mesh
          filename="../meshes/piper/link5.STL" />
      </geometry>
    </collision>
  </link>
  <joint
    name="arm_joint04"
    type="revolute">
    <origin
      xyz="0 0 0"
      rpy="-1.5708 0 0" />
    <parent
      link="arm_link04" />
    <child
      link="arm_link05" />
    <axis
      xyz="0 0 1" />
    <limit
      lower="-1.22"
      upper="1.22"
      effort="100"
      velocity="5" />
  </joint>
  <link
    name="gripper_link">
    <inertial>
      <origin 
        xyz="-8.82590762930069E-05 9.0598378529832E-06 -0.002" 
        rpy="0 0 0" />
      <mass 
        value="0.00699089613564366" />
      <inertia 
        ixx="5.73015540542155E-07" 
        ixy="-1.98305403089247E-22" 
        ixz="-7.2791893904596E-23" 
        iyy="5.73015540542155E-07" 
        iyz="-3.4146026640245E-24" 
        izz="1.06738869138926E-06" />
    </inertial>
    <visual>
      <origin
        xyz="0 0 0"
        rpy="0 0 0" />
      <geometry>
        <mesh
          filename="../meshes/piper/link6.STL" />
      </geometry>
      <material
        name="">
        <color
          rgba="0.898039215686275 0.917647058823529 0.929411764705882 1" />
      </material>
    </visual>
    <collision>
      <origin
        xyz="0 0 0"
        rpy="0 0 0" />
      <geometry>
        <mesh
          filename="../meshes/piper/link6.STL" />
      </geometry>
    </collision>
  </link>
  <joint
    name="arm_joint05"
    type="revolute">
    <origin
      xyz="8.8259E-05 -0.091 0"
      rpy="1.5708 0 0" />
    <parent
      link="arm_link05" />
    <child
      link="gripper_link" />
    <axis
      xyz="0 0 1" />
    <limit
      lower="-2.0944"
      upper="2.0944"
      effort="100"
      velocity="3" />
  </joint>
  <link
    name="gripper_base">
    <inertial>
      <origin
        xyz="-0.000183807162235591 8.05033155577911E-05 0.0321436689908876"
        rpy="0 0 0" />
      <mass
        value="0.45" />
      <inertia
        ixx="0.00092934"
        ixy="0.00000034"
        ixz="-0.00000738"
        iyy="0.00071447"
        iyz="0.00000005"
        izz="0.00039442" />
    </inertial>
    <visual>
      <origin
        xyz="0 0 0"
        rpy="0 0 0" />
      <geometry>
        <mesh
          filename="../meshes/piper/gripper_base.STL" />
      </geometry>
      <material
        name="">
        <color
          rgba="0.792156862745098 0.819607843137255 0.933333333333333 1" />
      </material>
    </visual>
    <collision>
      <origin
        xyz="0 0 0"
        rpy="0 0 0" />
      <geometry>
        <mesh
          filename="../meshes/piper/gripper_base.STL" />
      </geometry>
    </collision>
  </link> 
  <joint
    name="joint6_to_gripper_base"
    type="fixed">
    <origin
      xyz="0 0 0"
      rpy="0 0 0" />
    <parent
      link="gripper_link" />
    <child
      link="gripper_base" />
  </joint>
  <link
    name="gripper_link_right">
    <inertial>
      <origin
        xyz="0.00065123185041968 -0.0491929869131989 0.00972258769184025"
        rpy="0 0 0" />
      <mass
        value="0.025" />
      <inertia
        ixx="0.00007371"
        ixy="-0.00000113"
        ixz="0.00000021"
        iyy="0.00000781"
        iyz="-0.00001372"
        izz="0.0000747" />
    </inertial>
    <visual>
      <origin
        xyz="0 0 0"
        rpy="0 0 0" />
      <geometry>
        <mesh
          filename="../meshes/piper/link7.STL" />
      </geometry>
      <material
        name="">
        <color
          rgba="0.792156862745098 0.819607843137255 0.933333333333333 1" />
      </material>
    </visual>
    <collision>
      <origin
        xyz="0 0 0"
        rpy="0 0 0" />
      <geometry>
        <mesh
          filename="../meshes/piper/link7.STL" />
      </geometry>
    </collision>
  </link>
  <joint
    name="arm_joint06"
    type="fixed">
    <origin
      xyz="0 0 0.1358"
      rpy="1.5708 0 0" />
    <parent
      link="gripper_base" />
    <child
      link="gripper_link_right" />
    <axis
      xyz="0 0 1" />
    <limit
      lower="0"
      upper="0.035"
      effort="10"
      velocity="1" />
  </joint>
  <link
    name="gripper_link_left">
    <inertial>
      <origin
        xyz="0.000651231850419722 -0.0491929869131991 0.00972258769184024"
        rpy="0 0 0" />
      <mass
        value="0.025" />
      <inertia
        ixx="0.00007371"
        ixy="-0.00000113"
        ixz="0.00000021"
        iyy="0.00000781"
        iyz="-0.00001372"
        izz="0.0000747" />
    </inertial>
    <visual>
      <origin
        xyz="0 0 0"
        rpy="0 0 0" />
      <geometry>
        <mesh
          filename="../meshes/piper/link8.STL" />
      </geometry>
      <material
        name="">
        <color
          rgba="0.792156862745098 0.819607843137255 0.933333333333333 1" />
      </material>
    </visual>
    <collision>
      <origin
        xyz="0 0 0"
        rpy="0 0 0" />
      <geometry>
        <mesh
          filename="../meshes/piper/link8.STL" />
      </geometry>
    </collision>
  </link>
  <joint
    name="arm_joint07"
    type="fixed">
    <origin
      xyz="0 0 0.1358"
      rpy="1.5708 0 -3.1416" />
    <parent
      link="gripper_base" />
    <child
      link="gripper_link_left" />
    <axis
      xyz="0 0 -1" />
    <limit
      lower="-0.035"
      upper="0"
      effort="10"
      velocity="1" />
  </joint>

  <!-- left leg -->
  <link name="left_thigh">
    <inertial>
      <origin xyz="0.17494 0.0025294 0.012308" rpy="0 0 0" />
      <mass value="1.3343" />
      <inertia ixx="0.0012777" ixy="0.00031132" ixz="0.00051742" iyy="0.00919068" iyz="8.2e-06" izz="0.00982094" />
    </inertial>
    <visual>
      <origin xyz="0 0 0" rpy="0 0 0" />
      <geometry>
        <mesh filename="../meshes/chassis/left_thigh.STL" />
      </geometry>
      <material name="">
        <color rgba="0.75294 0.75294 0 1" />
      </material>
    </visual>
    <collision>
      <origin xyz="0 0 0" rpy="0 0 0" />
      <geometry>
        <mesh filename="../meshes/chassis/left_thigh.STL" />
      </geometry>
    </collision>
  </link>
  <joint name="left_hip" type="revolute">
    <origin xyz="0.017241 0.13399 0.0613" rpy="1.5708 1.5708 3.1416" />
    <parent link="base_link" />
    <child link="left_thigh" />
    <axis xyz="0 0 1" />
    <limit lower="-0.654" upper="2.225" effort="35" velocity="20" />
  </joint>
  <link name="left_shin">
    <inertial>
      <origin xyz="0.15612 0.00046249 0.020119" rpy="0 0 0" />
      <mass value="0.94398" />
      <inertia ixx="0.00075022" ixy="-3.818e-05" ixz="0.00046442" iyy="0.00358634" iyz="-8.81e-06" izz="0.00389927" />
    </inertial>
    <visual>
      <origin xyz="0 0 0" rpy="0 0 0" />
      <geometry>
        <mesh filename="../meshes/chassis/left_shin.STL" />
      </geometry>
      <material name="">
        <color rgba="0.75294 0.75294 0 1" />
      </material>
    </visual>
    <collision>
      <origin xyz="0 0 0" rpy="0 0 0" />
      <geometry>
        <mesh filename="../meshes/chassis/left_shin.STL" />
      </geometry>
    </collision>
  </link>
  <joint name="left_knee" type="revolute">
    <origin xyz="0.21 0 0.0475" rpy="0 0 0" />
    <parent link="left_thigh" />
    <child link="left_shin" />
    <axis xyz="0 0 1" />
    <limit lower="-2.243" upper="0" effort="35" velocity="20" />
  </joint>
  <link name="left_wheel">
    <inertial>
      <origin xyz="1.384E-13 1.3914E-13 0.0012686" rpy="0 0 0" />
      <mass value="0.44583" />
      <inertia ixx="0.00076522" ixy="0" ixz="0" iyy="0.00076522" iyz="0" izz="0.0014254" />
    </inertial>
    <visual>
      <origin xyz="0 0 0" rpy="0 0 0" />
      <geometry>
        <mesh filename="../meshes/chassis/left_wheel.STL" />
      </geometry>
      <material name="">
        <color rgba="0.75294 0 0 1" />
      </material>
    </visual>
    <collision>
      <origin xyz="0 0 0" rpy="0 0 0" />
      <geometry>
        <mesh filename="../meshes/chassis/left_wheel.STL" />
      </geometry>
    </collision>
  </link>
  <joint name="left_ankle" type="revolute">
    <origin xyz="0.18 0 0.0305" rpy="0 0 0" />
    <parent link="left_shin" />
    <child link="left_wheel" />
    <axis xyz="0 0 1" />
    <limit lower="-999999" upper="999999" effort="35" velocity="20" />  
     <!-- "   -->
  </joint>

</robot>